Workbook

Sheet Rates
A1: Date | B1: US=1 | C1: US=2 | D1: US=5 | E1: US=10 | F1: US=30 | G1: EU=1 | H1: EU=2 | I1: EU=5 | J1: EU=10 | K1: EU=30 | L1: DE=1 | M1: DE=2 | N1: DE=5 | O1: DE=10 | P1: DE=30 | Q1: FR=1 | R1: FR=2 | S1: FR=5 | T1: FR=10 | U1: FR=30 | V1: UK=1 | W1: UK=2 | X1: UK=5 | Y1: UK=10 | Z1: UK=30 | AA1: IT=1 | AB1: IT=2 | AC1: IT=5 | AD1: IT=10 | AE1: IT=30 | AF1: CH=1 | AG1: CH=2 | AH1: CH=5 | AI1: CH=10 | AJ1: CH=30 | AK1: JP=1 | AL1: JP=2 | AM1: JP=5 | AN1: JP=10 | AO1: JP=30
A2: 43831 | B2: =VLOOKUP(A2,Sheet2!$A$1:$B$1585,2,FALSE) -> 1.579
A3: 43832 | B3: =VLOOKUP(A3,Sheet2!$A$1:$B$1585,2,FALSE) -> #N/A
A4: 43833 | B4: =VLOOKUP(A4,Sheet2!$A$1:$B$1585,2,FALSE) -> #N/A
A5: 43834 | B5: =VLOOKUP(A5,Sheet2!$A$1:$B$1585,2,FALSE) -> 0.157
A6: 43835 | B6: =VLOOKUP(A6,Sheet2!$A$1:$B$1585,2,FALSE) -> 0.167
A7: 43836 | B7: =VLOOKUP(A7,Sheet2!$A$1:$B$1585,2,FALSE) -> 0.17
A8: 43837 | B8: =VLOOKUP(A8,Sheet2!$A$1:$B$1585,2,FALSE) -> 0.162
A9: 43838 | B9: =VLOOKUP(A9,Sheet2!$A$1:$B$1585,2,FALSE) -> #N/A | C9: =IF(A9=Sheet2!A1580,1,2) -> 2
A10: 43839 | B10: =VLOOKUP(A10,Sheet2!$A$1:$B$1585,2,FALSE) -> 0.122
A11: 43840 | B11: =VLOOKUP(A11,Sheet2!$A$1:$B$1585,2,FALSE) -> 0.117
A12: 43841 | B12: =VLOOKUP(A12,Sheet2!$A$1:$B$1585,2,FALSE) -> #N/A
A13: 43842 | B13: =VLOOKUP(A13,Sheet2!$A$1:$B$1585,2,FALSE) -> 0.107
A14: 43843 | B14: =VLOOKUP(A14,Sheet2!$A$1:$B$1585,2,FALSE) -> #N/A
A15: 43844 | B15: =VLOOKUP(A15,Sheet2!$A$1:$B$1585,2,FALSE) -> #N/A
A16: 43845 | B16: =VLOOKUP(A16,Sheet2!$A$1:$B$1585,2,FALSE) -> #N/A
A17: 43846 | B17: =VLOOKUP(A17,Sheet2!$A$1:$B$1585,2,FALSE) -> #N/A
A18: 43847 | B18: =VLOOKUP(A18,Sheet2!$A$1:$B$1585,2,FALSE) -> #N/A
A19: 43848 | B19: =VLOOKUP(A19,Sheet2!$A$1:$B$1585,2,FALSE) -> #N/A
A20: 43849 | B20: =VLOOKUP(A20,Sheet2!$A$1:$B$1585,2,FALSE) -> #N/A
A21: 43850 | B21: =VLOOKUP(A21,Sheet2!$A$1:$B$1585,2,FALSE) -> #N/A
... A2243: 46072 | B2243: =VLOOKUP(A2243,Sheet2!$A$1:$B$1585,2,FALSE) -> #N/A

Sheet Sheet2
A1: Date | B1: Price
A2: 02/19/2026 | B2: 3.509
A3: 02/18/2026 | B3: 3.491
A4: 02/17/2026 | B4: 3.476
A5: 02/16/2026 | B5: 3.431
A6: 02/13/2026 | B6: 3.426
A7: 46358 | B7: 3.453
A8: 46328 | B8: 3.467
A9: 46297 | B9: 3.406
A10: 46267 | B10: 3.433
A11: 46175 | B11: 3.446
A12: 46144 | B12: 3.447
A13: 46114 | B13: 3.49
A14: 46083 | B14: 3.498
A15: 46055 | B15: 3.496
A16: 01/30/2026 | B16: 3.477
A17: 01/29/2026 | B17: 3.494
A18: 01/28/2026 | B18: 3.518
A19: 01/27/2026 | B19: 3.505
A20: 01/26/2026 | B20: 3.513
A21: 01/23/2026 | B21: 3.527
A22: 01/22/2026 | B22: 3.533
A23: 01/21/2026 | B23: 3.531
A24: 01/20/2026 | B24: 3.529
A25: 01/19/2026 | B25: 3.567
A26: 01/16/2026 | B26: 3.553
A27: 01/15/2026 | B27: 3.539
... A29: 01/13/2026 | B29: 3.51
A30: 46357 | B30: 3.523
A31: 46266 | B31: 3.51
A32: 46235 | B32: 3.484
A33: 46204 | B33: 3.479
A34: 46174 | B34: 3.479
A35: 46143 | B35: 3.466
A36: 46054 | B36: 3.472
A37: 46023 | B37: 3.481
A38: 12/31/2025 | B38: 3.475
A39: 12/30/2025 | B39: 3.47
A40: 12/29/2025 | B40: 3.481
A41: 12/26/2025 | B41: 3.492
...
